<?xml version="1.0"?>
<robot xmlns:xacro="http://www.ros.org/wiki/xacro">

<!--WHERE THERE IS 'ABC' IT MEANS THE VALUE OR FIELD IS NOT DETERMINED YET-->
    <!--base to chassis joint-->
    <joint name='base_to_chassis_joint' type='fixed'>
        <parent link='base_link'/>
        <child link='chassis_link'/>
        <!--the origin tag over here means the origin of the join before any motion/transformation occurs-->
        <origin xyz='A B C' rpy='A B C'/>
    </joint>

    <!--Chassis to kingpin1 joint-->
    <joint name='chassis_to_kingpin1_joint' type='revolute'>
        <parent link='chassis_link'/>
        <child link='right_kingpin_link'/>
        <origin xyz='A B C' rpy='A B C'/>
        <axis xyz='A B C'/>
        <limit lower='-A' upper='+A' velocity='1' effot='25'/>   
    </joint>

      <!--Chassis to kingpin2 joint-->
    <joint name='chassis_to_kingpin2_joint' type='revolute'>
        <parent link='chassis_link'/>
        <child link='left_kingpin_link'/>
        <origin xyz='A B C' rpy='A B C'/>
        <axis xyz='A B C'/>
        <limit lower='-A' upper='+A' velocity='1' effot='25'/>   
    </joint>

    <!--Kingpin1 to wheel joint-->
    <joint name='kingpin1_to_front_right_wheel' type='continuous'>
        <parent link='right_kingpin_link'/>
        <child link='front_right_wheel_link'/>
        <!--steering wheel joints don't have origin as its at the kinpin link?-->
        <axis xyz='A B C'/>
    </joint>

    <!--Kingpin2 to wheel joint-->
    <joint name='kingpin2_to_front_left_wheel' type='continuous'>
        <parent link='left_kingpin_link'/>
        <child link='front_left_wheel_link'/>
        <axis xyz='A B C'/>
    </joint>

    <!--Chassis to wheel joint-->
    <joint name='chassis_to_rear_right_wheel' type='continuous'>
        <parent link='chassis_link'/>
        <child link='rear_right_wheel_link'/>
        <origin xyz='A B C' rpy='A B C'/>
        <axis xyz='A B C'/>
    </joint>

    <!--Chassis to wheel joint-->
    <joint name='chassis_to_rear_left_wheel' type='continuous'>
        <parent link='chassis_link'/>
        <child link='rear_left_wheel_link'/>
        <origin xyz='A B C' rpy='A B C'/>
        <axis xyz='A B C'/>
    </joint>

</robot>~